Workbook

Sheet Sheet2
A1: FECHA | B1: AV | C1: MAC | D1: TIPO | E1: PROPIEDAD | F1: identificacion | G1: NOMBRE | H1: CARGO | I1: TORRE | J1: CORREO | K1: ESTADO | L1: IP | M1: NOMBRE NANO
C2: b0:52:16:b7:1e:6c | D2: IMPRESORA | F2: 1006845199 | G2: Yuri Cenith Vera Rodriguez | I2: RIG 23 | J2: RIG23HSEQ@independence.com.co | K2: APROBADO | L2: 172.16.23.3
C3: A4:C3:BE:70:01:64 | D3: CELULAR | F3: 36294159 | G3: Yubelly Gómez Marlobiz Gómez | I3: RIG 31 | J3: rig31hseq@independence.com.co | K3: APROBADO | L3: APROBADO
C4: 00:2b:70:18:15:59 | D4: CELULAR | F4: 36304634 | G4: Yina Carmenza Useche Castro | I4: RIG 40 | J4: ycuseche@independence.com.co | K4: APROBADO | L4: 172.16.40.3
C5: D8:F8:83:BC:08:40 | D5: PC | F5: 36304634 | G5: Yina Carmenza Useche Castro | I5: RIG 40 | J5: ycuseche@independence.com.co | K5: APROBADO | L5: 172.16.40.3
C6: 00:2b:70:18:15:59 | D6: CELULAR | F6: 36304634 | G6: Yina Carmenza Useche Castro | I6: RIG 40 | J6: ycuseche@independence.com.co | K6: APROBADO | L6: 172.16.40.4
C7: D8:F8:83:BC:08:40 | D7: PC | F7: 36304634 | G7: Yina Carmenza Useche Castro | I7: RIG 40 | J7: ycuseche@independence.com.co | K7: APROBADO | L7: 172.16.40.4
C8: 00:2b:70:18:15:59 | D8: CELULAR | F8: 36304634 | G8: Yina Carmenza Useche Castro | I8: RIG 40 | J8: ycuseche@independence.com.co | K8: APROBADO | L8: 172.16.40.5
C9: D8:F8:83:BC:08:40 | D9: PC | F9: 36304634 | G9: Yina Carmenza Useche Castro | I9: RIG 40 | J9: ycuseche@independence.com.co | K9: APROBADO | L9: 172.16.40.5
C10: 00:2b:70:18:15:59 | D10: CELULAR | F10: 36304634 | G10: Yina Carmenza Useche Castro | I10: RIG 122 | J10: ycuseche@independence.com.co | K10: APROBADO | L10: 172.16.122.3
C11: D8:F8:83:BC:08:40 | D11: PC | F11: 36304634 | G11: Yina Carmenza Useche Castro | I11: RIG 122 | J11: ycuseche@independence.com.co | K11: APROBADO | L11: 172.16.122.3
C12: 00:2b:70:18:15:59 | D12: CELULAR | F12: 36304634 | G12: Yina Carmenza Useche Castro | I12: RIG 122 | J12: ycuseche@independence.com.co | K12: APROBADO | L12: 172.16.122.4
C13: D8:F8:83:BC:08:40 | D13: PC | F13: 36304634 | G13: Yina Carmenza Useche Castro | I13: RIG 122 | J13: ycuseche@independence.com.co | K13: APROBADO | L13: 172.16.122.4
... C25: 48:9E:BD:49:53:AC | D25: PC | F25: 1121846714 | G25: Yeison Alejandro Castillo Prado | I25: RIG 122 | J25: jefeoperacionesdrilling@independence.com.co | K25: APROBADO | L25: APROBADO
A26: 2025-11-17T08:00:00Z | C26: F4:2B:8C:F3:48:87 | D26: CELULAR | E26: Personal | F26: 1121846714 | G26: Yeison Alejandro Castillo Prado | I26: RIG 61 | J26: jefeoperacionesdrilling@independence.com.co | K26: APROBADO | L26: 172.16.61.3
A27: 2025-11-17T08:00:00Z | C27: F4:2B:8C:F3:48:87 | D27: CELULAR | E27: Personal | F27: 1121846714 | G27: Yeison Alejandro Castillo Prado | I27: RIG 61 | J27: jefeoperacionesdrilling@independence.com.co | K27: APROBADO | L27: 172.16.61.4
A28: 2025-11-17T08:00:00Z | C28: 48:9E:BD:49:53:AC | D28: PC | E28: Corporativo | F28: 1121846714 | G28: Yeison Alejandro Castillo Prado | I28: RIG 61 | J28: jefeoperacionesdrilling@independence.com.co | K28: APROBADO | L28: 172.16.61.3
A29: 2025-11-17T08:00:00Z | C29: 48:9E:BD:49:53:AC | D29: PC | E29: Corporativo | F29: 1121846714 | G29: Yeison Alejandro Castillo Prado | I29: RIG 61 | J29: jefeoperacionesdrilling@independence.com.co | K29: APROBADO | L29: 172.16.61.4
A30: 2025-11-15T08:00:00Z | C30: 9C:50:D1:82:82:9E | D30: CELULAR | E30: Corporativo | F30: 17596779 | G30: YADIN PEROZA LOZANO | I30: RIG 45 | J30: rig45@independence.com.co | K30: APROBADO | L30: 172.16.45.4
A31: 2025-11-15T08:00:00Z | C31: 9C:50:D1:82:82:9E | D31: CELULAR | E31: Corporativo | F31: 17596779 | G31: YADIN PEROZA LOZANO | I31: RIG 45 | J31: rig45@independence.com.co | K31: APROBADO | L31: 172.16.45.3
A32: 2025-11-15T08:00:00Z | C32: 9C:50:D1:82:82:9E | D32: CELULAR | E32: Corporativo | F32: 17596779 | G32: YADIN PEROZA LOZANO | I32: RIG 36 | J32: rig45@independence.com.co | K32: APROBADO | L32: 172.16.36.3
A33: 2025-11-15T08:00:00Z | C33: 9C:50:D1:82:82:9E | D33: CELULAR | E33: Corporativo | F33: 17596779 | G33: YADIN PEROZA LOZANO | I33: RIG 36 | J33: rig45@independence.com.co | K33: APROBADO | L33: 172.16.36.4
C34: FC:B5:86:A4:CA:84 | D34: BIOMÉTRICO | F34: 1052396787 | G34: Xiomara Suarez | I34: RIG 204 | J34: jxsuarez@independence.com.co | K34: APROBADO | L34: 172.16.204.8
C35: FC:B5:86:A4:CA:84 | D35: BIOMÉTRICO | F35: 1052396787 | G35: Xiomara Suarez | I35: RIG 204 | J35: jxsuarez@independence.com.co | K35: APROBADO | L35: 172.16.204.4
C36: FC:B5:86:A4:CA:84 | D36: BIOMÉTRICO | F36: 1052396787 | G36: Xiomara Suarez | I36: RIG 204 | J36: jxsuarez@independence.com.co | K36: APROBADO | L36: 172.16.204.2
C37: FC:B5:86:A4:CA:84 | D37: BIOMÉTRICO | F37: 1052396787 | G37: Xiomara Suarez | I37: RIG 204 | J37: jxsuarez@independence.com.co | K37: APROBADO | L37: 172.16.204.6
C38: FC:B5:86:A4:CA:84 | D38: BIOMÉTRICO | F38: 1052396787 | G38: Xiomara Suarez | I38: RIG 204 | J38: jxsuarez@independence.com.co | K38: APROBADO | L38: 172.16.204.5
C39: FC:B5:86:A4:CA:84 | D39: BIOMÉTRICO | F39: 1052396787 | G39: Xiomara Suarez | I39: RIG 204 | J39: jxsuarez@independence.com.co | K39: APROBADO | L39: 172.16.204.3
C40: FC:B5:86:A4:CA:84 | D40: BIOMÉTRICO | F40: 1052396787 | G40: Xiomara Suarez | I40: RIG 204 | J40: jxsuarez@independence.com.co | K40: APROBADO | L40: 172.16.204.7
C41: 1e:87:b4:24:21:3f | D41: CELULAR | G41: WILMER ARCHILA | I41: RIG 15 | J41: wilmer.archila@ecopetrol.com.co | K41: APROBADO | L41: 172.16.15.3
C42: 1e:87:b4:24:21:3f | D42: CELULAR | G42: WILMER ARCHILA | I42: RIG 15 | J42: wilmer.archila@ecopetrol.com.co | K42: APROBADO | L42: 172.16.15.4
C43: 1e:87:b4:24:21:3f | D43: CELULAR | G43: WILMER ARCHILA | I43: RIG 15 | J43: wilmer.archila@ecopetrol.com.co | K43: APROBADO | L43: 172.16.15.5
C44: C4:EF:3D:E7:3A:37 | D44: CELULAR | F44: 7709212 | G44: Wilfor Trujillo Pascuas. | I44: RIG 221 | J44: rig221@independence.com.co | K44: APROBADO | L44: 172.16.221.3
C45: C4:EF:3D:E7:3A:37 | D45: CELULAR | F45: 7709212 | G45: Wilfor Trujillo Pascuas. | I45: RIG 221 | J45: rig221@independence.com.co | K45: APROBADO | L45: 172.16.221.4
C46: C4:EF:3D:E7:3A:37 | D46: CELULAR | F46: 7709212 | G46: Wilfor Trujillo Pascuas. | I46: RIG 221 | J46: rig221@independence.com.co | K46: APROBADO | L46: 172.16.221.5
C47: D0:65:78:6D:8B:57 | D47: PC | G47: WILBER CASTAÑEDA | I47: CB-GUAMAL | J47: wilber.castaneda@ecopetrol.com.co | K47: APROBADO | L47: 172.16.5.5
C48: D0:65:78:6D:8B:57 | D48: PC | G48: WILBER CASTAÑEDA | I48: CB-GUAMAL | J48: wilber.castaneda@ecopetrol.com.co | K48: APROBADO | L48: 172.16.5.4
C49: D0:65:78:6D:8B:57 | D49: PC | G49: WILBER CASTAÑEDA | I49: CB-GUAMAL | J49: wilber.castaneda@ecopetrol.com.co | K49: APROBADO | L49: 172.16.5.3
C50: 50:50:A4:49:2B:D4 | D50: CELULAR | G50: Warllen romero | I50: RIG 28 | J50: rig28mantenimiento@independence.com.co | K50: APROBADO | L50: 172.16.28.3
C51: 50:50:A4:49:2B:D4 | D51: CELULAR | G51: Warllen romero | I51: RIG 28 | J51: rig28mantenimiento@independence.com.co | K51: APROBADO | L51: 172.16.28.4
...

Sheet fallos
A1: FECHA | B1: AV | C1: MAC | D1: TIPO | E1: PROPIEDAD | F1: IDENTIFICACION | G1: NOMBRE | H1: CARGO | I1: TORRE | J1: CORREO | K1: IP | L1: ESTADO
A2: 2025-11-27T08:00:00Z | C2: BC:5E:91:EE:9E:20 | D2: CELULAR | E2: Personal | F2: =+VLOOKUP(G2,Sheet2!$1:$1048576,6,FALSE) | G2: SANTOS TOLEDO CORTEZ | I2: RIG 122 | J2: rig122mantenimiento@independence.com.co | K2: 172.16.122.8 | L2: ERROR
A3: 2025-11-28T08:00:00Z | C3: 64:a2:00:85:a0:1c | D3: CELULAR | E3: Personal | F3: =+VLOOKUP(G3,Sheet2!$1:$1048576,6,FALSE) | G3: Fredy Alejandro baracaldo Díaz | I3: RIG 204 | J3: fabaracaldo@independence.com.co | K3: 172.16.204.8 | L3: ERROR
A4: 2025-11-28T08:00:00Z | C4: 64:a2:00:85:a0:1c | D4: CELULAR | E4: Personal | F4: =+VLOOKUP(G4,Sheet2!$1:$1048576,6,FALSE) | G4: Fredy Alejandro baracaldo Díaz | I4: RIG 204 | J4: fabaracaldo@independence.com.co | K4: 172.16.204.2 | L4: ERROR
A5: 2025-11-28T08:00:00Z | C5: 64:a2:00:85:a0:1c | D5: CELULAR | E5: Personal | F5: =+VLOOKUP(G5,Sheet2!$1:$1048576,6,FALSE) | G5: Fredy Alejandro baracaldo Díaz | I5: RIG 204 | J5: fabaracaldo@independence.com.co | K5: 172.16.204.3 | L5: ERROR
A6: 2025-11-28T08:00:00Z | C6: 70:15:FB:67:25:05 | D6: PC | E6: Corporativo | F6: =+VLOOKUP(G6,Sheet2!$1:$1048576,6,FALSE) | G6: Ricardo Correa | I6: RIG 225 | J6: rig225hseq@independence.com.co | K6: 172.16.225.4 | L6: ERROR
A7: 2025-11-28T08:00:00Z | C7: C4:BD:E5:6C:9E:D1 | D7: PC | E7: Corporativo | F7: =+VLOOKUP(G7,Sheet2!$1:$1048576,6,FALSE) | G7: LUIS GUILLERMO MERCADO | I7: RIG 225 | J7: rig225hseq@independence.com.co | K7: 172.16.225.4 | L7: ERROR
A8: 2025-11-28T08:00:00Z | C8: C8:6E:08:8D:BB:C0 | D8: PC | E8: Corporativo | F8: =+VLOOKUP(G8,Sheet2!$1:$1048576,6,FALSE) | G8: Fredy Alejandro baracaldo Díaz | I8: RIG 204 | J8: fabaracaldo@independence.com.co | K8: 172.16.204.8 | L8: ERROR
A9: 2025-11-28T08:00:00Z | C9: C8:6E:08:8D:BB:C0 | D9: PC | E9: Corporativo | F9: =+VLOOKUP(G9,Sheet2!$1:$1048576,6,FALSE) | G9: Fredy Alejandro baracaldo Díaz | I9: RIG 204 | J9: fabaracaldo@independence.com.co | K9: 172.16.204.3 | L9: ERROR
A10: 2025-11-28T08:00:00Z | C10: e4:57:68:23:bf:57 | D10: CELULAR | E10: Personal | F10: =+VLOOKUP(G10,Sheet2!$1:$1048576,6,FALSE) | G10: javier alfaro | I10: RIG 42 | J10: jefeequiporig42@independence.com.co | K10: 172.16.42.4 | L10: ERROR
A11: 2025-12-01T08:00:00Z | C11: 80:77:a4:af:b6:e5 | D11: CELULAR | E11: Personal | F11: =+VLOOKUP(G11,Sheet2!$1:$1048576,6,FALSE) | G11: Víctor Padilla | I11: RIG 204 | J11: rig204mantenimiento@independence.com.co | K11: 172.16.204.8 | L11: ERROR
A12: 2025-12-01T08:00:00Z | C12: 80:77:a4:af:b6:e5 | D12: CELULAR | E12: Personal | F12: =+VLOOKUP(G12,Sheet2!$1:$1048576,6,FALSE) | G12: Víctor Padilla | I12: RIG 204 | J12: rig204mantenimiento@independence.com.co | K12: 172.16.204.2 | L12: ERROR
A13: 2025-12-01T08:00:00Z | C13: 80:77:a4:af:b6:e5 | D13: CELULAR | E13: Personal | F13: =+VLOOKUP(G13,Sheet2!$1:$1048576,6,FALSE) | G13: Víctor Padilla | I13: RIG 204 | J13: rig204mantenimiento@independence.com.co | K13: 172.16.204.3 | L13: ERROR
... A41: 2025-12-03T08:00:00Z | C41: 5C:DC:49:8A:E7:85 | D41: CELULAR | E41: Personal | F41: =+VLOOKUP(G41,Sheet2!$1:$1048576,6,FALSE) | G41: Rafael Eduardo Valbuena Hernandez | I41: RIG 42 | J41: jefeoperacionesputumayo@independence.com.co | K41: 172.16.42.4 | L41: ERROR
